Workbook
Name SegmentaciónDeDatos_age: #N/A
Name SegmentaciónDeDatos_age1: #N/A
Name SegmentaciónDeDatos_country: #N/A
Name SegmentaciónDeDatos_country1: #N/A
Name SegmentaciónDeDatos_headshot_percentage: #N/A

Sheet Introduccion
A1: ¡BIENVENIDOS! El presente trabajo tiene como objetivo realizar un análisis estadístico exhaustivo sobre el rendimiento de jugadores profesionales del videojuego Counter-Strike: Global Offensive (CS:GO), a partir de una base de datos construida con información cuantitativa relevante del entorno competitivo. A lo largo del documento se desarrollan distintos apartados que permiten visualizar, interpretar y segmentar los datos recogidos. Se analiza un conjunto de más de 800 jugadores, considerando variables como la edad, nacionalidad, equipo actual, historial de equipos, y un amplio conjunto de métricas de desempeño individual: muertes, asesinatos, daño por ronda, precisión de disparos a la cabeza, uso de distintos tipos de armas, entre otras. El análisis se apoya en el uso de tablas dinámicas y dashboards interactivos, que permiten identificar patrones, comparaciones y relaciones entre variables. Asimismo, se responde a una serie de preguntas analíticas orientadas a descubrir: • Las edades más frecuentes entre los jugadores profesionales. • Las armas con mayor índice de efectividad. • La relación entre el desempeño individual y los equipos a los que pertenecen los jugadores. El enfoque adoptado busca no solo presentar los datos de forma estructurada, sino también facilitar su interpretación mediante recursos visuales e indicadores clave de desempeño. Este estudio proporciona una base sólida para la comprensión de las dinámicas individuales dentro del ecosistema profesional de CS:GO. Fuente: https://www.kaggle.com/datasets/naumanaarif/csgo-pro-players-dataset https://www.hltv.org/

Sheet DashBoard
B3: Jugadores | E3: Kills | H3: Muertes | K3: Rating | N3: Rifle Kills | Q3: Sniper Kills | T3: Pistol Kills
B5: =GETPIVOTDATA("country",'Tabla dinamica 2'!$H$3) -> 28 | E5: =GETPIVOTDATA("Suma de total_kills",'Tabla dinamica 2'!$A$3) -> 360586 | H5: =GETPIVOTDATA("Suma de total_deaths",'Tabla dinamica 2'!$A$3) -> 342463 | K5: =E5/H5 -> 1.0529196 | N5: =GETPIVOTDATA("Suma de rifle_kills",'Tabla dinamica 1'!$A$5) -> 235098 | Q5: =GETPIVOTDATA("Suma de sniper_kills",'Tabla dinamica 1'!$A$5) -> 32640 | T5: =GETPIVOTDATA("Suma de pistol_kills",'Tabla dinamica 1'!$A$5) -> 62771
Q34: ,

Sheet Tabla dinamica 1
A1: age | B1: (Todas)
A2: nickname | B2: (Todas)
A3: headshot_percentage | B3: (Todas)
A5: Country | B5: Suma de rifle_kills | C5: Suma de sniper_kills | D5: Suma de smg_kills | E5: Suma de pistol_kills | F5: Suma de grenade_kills
A6: China | B6: 235098 | C6: 32640 | D6: 25252 | E6: 62771 | F6: 3801
A7: Total general | B7: 235098 | C7: 32640 | D7: 25252 | E7: 62771 | F7: 3801

Sheet Tabla dinamica 2
A3: Country | B3: Suma de total_kills | C3: Suma de total_deaths | H3: Country | I3: Cantidad de Jugadores
A4: China | B4: 360586 | C4: 342463 | H4: China | I4: 28
A5: Total general | B5: 360586 | C5: 342463 | H5: Total general | I5: 28

Sheet Dashboard 2
D1: Jugadores | H1: KPI
D3: =GETPIVOTDATA("country",'Tabla dinamica 3|4'!$P$18) -> 8 | H3: =GETPIVOTDATA("Suma de KPI",'Tabla dinamica 3|4'!$A$20) -> 28415.224

Sheet Tabla dinamica 3|4
A3: Etiquetas de fila | B3: Suma de KPI | C3: Máx. de KPI2 | D3: Promedio de KPI2 | E3: Mín. de KPI2
A4: Alto | B4: 5152.1579 | C4: 5152.1579 | D4: 5152.1579 | E4: 5152.1579
A5: Bajo | B5: 11520.961 | C5: 3188.9474 | D5: 2880.2401 | E5: 2626.75
A6: Medio | B6: 11742.105 | C6: 4016.1579 | D6: 3914.0351 | E6: 3861.2105
A7: Total general | B7: 28415.224 | C7: 5152.1579 | D7: 3551.903 | E7: 2626.75
P18: Country | Q18: Cantidad de Jugadores
P19: Argentina | Q19: 8
A20: Country | B20: Suma de KPI | C20: Suma de KPI2 | P20: Total general | Q20: 8
A21: Argentina | B21: 28415.224 | C21: 1
A22: Total general | B22: 28415.224

Sheet Preguntas
D1: 3.Variedad de Edad y Promedio
A2: 1. Cantidad de jugadores. | D2: Edad | E2: Cantidad de jugadores con esa edad
A3: 811 | D3: 17 | E3: =COUNTIF(Dataset_original!D2:D812,Preguntas!D3) -> 1
A4: 2. Cantidad de paises y Jugadores que lo representan. | D4: 18 | E4: =COUNTIF(Dataset_original!D3:D813,Preguntas!D4) -> 5
A5: Pais | B5: Cantidad | D5: 19 | E5: =COUNTIF(Dataset_original!D4:D814,Preguntas!D5) -> 15 | G5: 6.Top jugadores por métricas específicas | J5: 9.Cantidad de equipos diferentes
A6: Argentina | B6: =COUNTIF(Dataset_original!E23:E833,Preguntas!A27) -> 16 | D6: 20 | E6: =COUNTIF(Dataset_original!D5:D815,Preguntas!D6) -> 32 | G6: Headshot % (Top 5) | J6: 257
A7: Australia | B7: =COUNTIF(Dataset_original!E48:E858,Preguntas!A52) -> 10 | D7: 21 | E7: =COUNTIF(Dataset_original!D6:D816,Preguntas!D7) -> 44 | G7: Jugador | H7: % Headshots
A8: Belarus | B8: =COUNTIF(Dataset_original!E33:E843,Preguntas!A37) -> 5 | D8: 22 | E8: =COUNTIF(Dataset_original!D7:D817,Preguntas!D8) -> 59 | G8: ScreaM | H8: 68.1% | J8: 10. Jugadores representado al equipo
A9: Belgium | B9: =COUNTIF(Dataset_original!E27:E837,Preguntas!A31) -> 6 | D9: 23 | E9: =COUNTIF(Dataset_original!D8:D818,Preguntas!D9) -> 64 | G9: b1t | H9: 67.9% | J9: Equipo | K9: Cantidad de jugadores
A10: Bosnia and Herzegovina | B10: =COUNTIF(Dataset_original!E19:E829,Preguntas!A23) -> 8 | D10: 24 | E10: =COUNTIF(Dataset_original!D9:D819,Preguntas!D10) -> 84 | G10: grux | H10: 67.1% | J10: No team | K10: =COUNTIF(Tabla2[current_team],Preguntas!J10) -> 297
A11: Brazil | B11: =COUNTIF(Dataset_original!E49:E859,Preguntas!A53) -> 6 | D11: 25 | E11: =COUNTIF(Dataset_original!D10:D820,Preguntas!D11) -> 90 | G11: b0RUP | H11: 63.8% | J11: K23 | K11: =COUNTIF(Tabla2[current_team],Preguntas!J11) -> 3
A12: Bulgaria | B12: =COUNTIF(Dataset_original!E45:E855,Preguntas!A49) -> 53 | D12: 26 | E12: =COUNTIF(Dataset_original!D11:D821,Preguntas!D12) -> 83 | G12: Grus | H12: 63.7% | J12: ex-Maknitude | K12: =COUNTIF(Tabla2[current_team],Preguntas!J12) -> 1
A13: Canada | B13: =COUNTIF(Dataset_original!E41:E851,Preguntas!A45) -> 3 | D13: 27 | E13: =COUNTIF(Dataset_original!D12:D822,Preguntas!D13) -> 73 | J13: Outsiders | K13: =COUNTIF(Tabla2[current_team],Preguntas!J13) -> 5
A14: China | B14: =COUNTIF(Dataset_original!E43:E853,Preguntas!A47) -> 5 | D14: 28 | E14: =COUNTIF(Dataset_original!D13:D823,Preguntas!D14) -> 71 | J14: HAVU | K14: =COUNTIF(Tabla2[current_team],Preguntas!J14) -> 8
A15: Czech Republic | B15: =COUNTIF(Dataset_original!E30:E840,Preguntas!A34) -> 7 | D15: 29 | E15: =COUNTIF(Dataset_original!D14:D824,Preguntas!D15) -> 47 | J15: Nemiga | K15: =COUNTIF(Tabla2[current_team],Preguntas!J15) -> 3
A16: Denmark | B16: =COUNTIF(Dataset_original!E54:E864,Preguntas!A58) -> 1 | D16: 30 | E16: =COUNTIF(Dataset_original!D15:D825,Preguntas!D16) -> 38 | J16: Entropiq | K16: =COUNTIF(Tabla2[current_team],Preguntas!J16) -> 6
A17: Estonia | B17: =COUNTIF(Dataset_original!E31:E841,Preguntas!A35) -> 1 | D17: 31 | E17: =COUNTIF(Dataset_original!D16:D826,Preguntas!D17) -> 28 | G17: 7.Rating más alto | J17: VRTX | K17: =COUNTIF(Tabla2[current_team],Preguntas!J17) -> 2
A18: Finland | B18: =COUNTIF(Dataset_original!E44:E854,Preguntas!A48) -> 9 | D18: 32 | E18: =COUNTIF(Dataset_original!D17:D827,Preguntas!D18) -> 33 | G18: Jugador | H18: Rating | J18: ODDIK | K18: =COUNTIF(Tabla2[current_team],Preguntas!J18) -> 1
A19: France | B19: =COUNTIF(Dataset_original!E47:E857,Preguntas!A51) -> 1 | D19: 33 | E19: =COUNTIF(Dataset_original!D18:D828,Preguntas!D19) -> 15 | G19: ZywOo | H19: 1.32 | J19: Heroic | K19: =COUNTIF(Tabla2[current_team],Preguntas!J19) -> 7
A20: Germany | B20: =COUNTIF(Dataset_original!E46:E856,Preguntas!A50) -> 2 | D20: 34 | E20: =COUNTIF(Dataset_original!D19:D829,Preguntas!D20) -> 13 | G20: sh1ro | H20: 1.26 | J20: cowana | K20: =COUNTIF(Tabla2[current_team],Preguntas!J20) -> 4
A21: Guatemala | B21: =COUNTIF(Dataset_original!E3:E813,Preguntas!A7) -> 44 | D21: 35 | E21: =COUNTIF(Dataset_original!D20:D830,Preguntas!D21) -> 9 | G21: s1mple | H21: 1.25 | J21: HellRaisers | K21: =COUNTIF(Tabla2[current_team],Preguntas!J21) -> 1
A22: Hong Kong | B22: =COUNTIF(Dataset_original!E7:E817,Preguntas!A11) -> 60 | D22: 36 | E22: =COUNTIF(Dataset_original!D21:D831,Preguntas!D22) -> 1 | G22: deko | H22: 1.23 | J22: Cloud9 | K22: =COUNTIF(Tabla2[current_team],Preguntas!J22) -> 5
A23: Hungary | B23: =COUNTIF(Dataset_original!E26:E836,Preguntas!A30) -> 5 | D23: Promedio de edad | E23: =AVERAGE(Dataset_original!D2:D812) -> 25.852035 | G23: blameF | H23: 1.22 | J23: Evil Geniuses | K23: =COUNTIF(Tabla2[current_team],Preguntas!J23) -> 4
A24: Indonesia | B24: =COUNTIF(Dataset_original!E16:E826,Preguntas!A20) -> 25 | J24: MOUZ NXT | K24: =COUNTIF(Tabla2[current_team],Preguntas!J24) -> 3
A25: Israel | B25: =COUNTIF(Dataset_original!E14:E824,Preguntas!A18) -> 26 | D25: 4. Kills promedio por tipo de arma | J25: Enterprise | K25: =COUNTIF(Tabla2[current_team],Preguntas!J25) -> 2
A26: Jordan | B26: =COUNTIF(Dataset_original!E8:E818,Preguntas!A12) -> 23 | D26: Tipo de arma | E26: Promedio por jugador | J26: temp | K26: =COUNTIF(Tabla2[current_team],Preguntas!J26) -> 5
A27: Kazakhstan | B27: =COUNTIF(Dataset_original!E40:E850,Preguntas!A44) -> 10 | D27: Rifle | E27: =AVERAGE(Tabla2[rifle_kills]) -> 9498.5845 | G27: 8. Promedios de Rondas y Mapas jugados | J27: ONET4P | K27: =COUNTIF(Tabla2[current_team],Preguntas!J27) -> 3
A28: Korea | B28: =COUNTIF(Dataset_original!E15:E825,Preguntas!A19) -> 25 | D28: Sniper | E28: =AVERAGE(Tabla2[sniper_kills]) -> 2115.836 | G28: Columna1 | H28: Columna2 | J28: EG.CD | K28: =COUNTIF(Tabla2[current_team],Preguntas!J28) -> 4
A29: Kosovo | B29: =COUNTIF(Dataset_original!E13:E823,Preguntas!A17) -> 6 | D29: Subfusil (SMG) | E29: =AVERAGE(Tabla2[smg_kills]) -> 840.59433 | H29: Promedio | J29: Unique | K29: =COUNTIF(Tabla2[current_team],Preguntas!J29) -> 2
A30: Latvia | B30: =COUNTIF(Dataset_original!E20:E830,Preguntas!A24) -> 2 | D30: Pistola | E30: =AVERAGE(Tabla2[pistol_kills]) -> 2643.2713 | G30: Mapas | H30: =AVERAGE(Tabla2[maps_played]) -> 843.34772 | J30: Corinthians | K30: =COUNTIF(Tabla2[current_team],Preguntas!J30) -> 3
A31: Lithuania | B31: =COUNTIF(Dataset_original!E21:E831,Preguntas!A25) -> 3 | D31: Granada | E31: =AVERAGE(Tabla2[grenade_kills]) -> 197.34895 | G31: Rondas | H31: =AVERAGE(Tabla2[rounds_played]) -> 22172.041 | J31: Endpoint | K31: =COUNTIF(Tabla2[current_team],Preguntas!J31) -> 4
A32: Malaysia | B32: =COUNTIF(Dataset_original!E10:E820,Preguntas!A14) -> 28 | D32: Otros | E32: =AVERAGE(Tabla2[other_kills]) -> 65.076449 | J32: MOUZ | K32: =COUNTIF(Tabla2[current_team],Preguntas!J32) -> 8
A33: Mexico | B33: =COUNTIF(Dataset_original!E9:E819,Preguntas!A13) -> 25 | J33: TeamOne | K33: =COUNTIF(Tabla2[current_team],Preguntas!J33) -> 6
A34: Mongolia | B34: =COUNTIF(Dataset_original!E24:E834,Preguntas!A28) -> 3 | J34: VERTEX | K34: =COUNTIF(Tabla2[current_team],Preguntas!J34) -> 4
A35: Montenegro | B35: =COUNTIF(Dataset_original!E6:E816,Preguntas!A10) -> 2 | D35: 5. Top 5 jugadores por cantidad de kills | J35: BIG | K35: =COUNTIF(Tabla2[current_team],Preguntas!J35) -> 6
A36: Netherlands | B36: =COUNTIF(Dataset_original!E22:E832,Preguntas!A26) -> 1 | D36: Jugador | E36: Kills totales | J36: Complexity | K36: =COUNTIF(Tabla2[current_team],Preguntas!J36) -> 7
A37: New Zealand | B37: =COUNTIF(Dataset_original!E28:E838,Preguntas!A32) -> 0 | D37: f0rest | E37: 40979 | J37: Sprout | K37: =COUNTIF(Tabla2[current_team],Preguntas!J37) -> 4
A38: North Macedonia | B38: =COUNTIF(Dataset_original!E4:E814,Preguntas!A8) -> 9 | D38: Snax | E38: 39509 | J38: Sampi | K38: =COUNTIF(Tabla2[current_team],Preguntas!J38) -> 1
A39: Norway | B39: =COUNTIF(Dataset_original!E39:E849,Preguntas!A43) -> 62 | D39: bubble | E39: 38738 | J39: FLET | K39: =COUNTIF(Tabla2[current_team],Preguntas!J39) -> 3
A40: Poland | B40: =COUNTIF(Dataset_original!E50:E860,Preguntas!A54) -> 22 | D40: shox | E40: 38675 | J40: ENCE | K40: =COUNTIF(Tabla2[current_team],Preguntas!J40) -> 6
...

Sheet Dataset_original
A1: player_id | B1: nickname | C1: real_name | D1: age | E1: country | F1: current_team | G1: teams | H1: total_kills | I1: total_deaths | J1: headshot_percentage | K1: damage_per_round | L1: grenade_dmg_per_round | M1: maps_played | N1: rounds_played | O1: kills_per_round | P1: assists_per_round | Q1: deaths_per_round | R1: saved_by_teammate_per_round | S1: saved_teammates_per_round | T1: rounds_with_kills | U1: kill_to_death_diff | V1: total_opening_kills | W1: total_opening_deaths | X1: opening_kill_ratio | Y1: opening_kill_rating | Z1: team_win_percent_after_first_kill | AA1: first_kill_in_won_rounds | AB1: 0_kill_rounds | AC1: 1_kill_rounds | AD1: 2_kill_rounds | AE1: 3_kill_rounds | AF1: 4_kill_rounds | AG1: 5_kill_rounds | AH1: rifle_kills | AI1: sniper_kills | AJ1: smg_kills | AK1: pistol_kills | AL1: grenade_kills | AM1: other_kills | AN1: rating
A2: 11893 | B2: ZywOo | C2: Mathieu Herbaut | D2: 21 | E2: France | F2: Vitality | G2: Vitality, aAa | H2: 22622 | I2: 16458 | J2: 41.20% | K2: 88 | L2: 3.6 | M2: 1020 | N2: 26803 | O2: 0.84 | P2: 0.12 | Q2: 0.61 | R2: 0.1 | S2: 0.12 | T2: 14196 | U2: K - D diff. | V2: 4152 | W2: 2592 | X2: 1.6 | Y2: 1.28 | Z2: 73.10% | AA2: 21.40% | AB2: 12607 | AC2: 8195 | AD2: 4087 | AE2: 1474 | AF2: 369 | AG2: 71 | AH2: 8261 | AI2: 8552 | AJ2: 1290 | AK2: 4262 | AL2: 260 | AM2: 49 | AN2: 1.32
A3: 7998 | B3: s1mple | C3: Aleksandr Kostyliev | D3: 24 | E3: Ukraine | F3: Natus Vincere | G3: Natus Vincere | H3: 35512 | I3: 26413 | J3: 41.30% | K3: 86.4 | L3: 2.4 | M3: 1571 | N3: 41491 | O3: 0.86 | P3: 0.1 | Q3: 0.64 | R3: 0.08 | S3: 0.11 | T3: 22559 | U3: K - D diff. | V3: 6014 | W3: 3734 | X3: 1.61 | Y3: 1.24 | Z3: 75.20% | AA3: 20.80% | AB3: 18932 | AC3: 13085 | AD3: 6644 | AE3: 2262 | AF3: 504 | AG3: 64 | AH3: 14717 | AI3: 13451 | AJ3: 901 | AK3: 6057 | AL3: 199 | AM3: 254 | AN3: 1.25
A4: 16920 | B4: sh1ro | C4: Dmitry Sokolov | D4: 21 | E4: Russia | F4: Cloud9 | G4: Gambit Youngsters, Gambit | H4: 18091 | I4: 12492 | J4: 27.80% | K4: 78.6 | L4: 3.9 | M4: 884 | N4: 23451 | O4: 0.77 | P4: 0.11 | Q4: 0.53 | R4: 0.08 | S4: 0.11 | T4: 11950 | U4: K - D diff. | V4: 2705 | W4: 1383 | X4: 1.96 | Y4: 1.15 | Z4: 77.00% | AA4: 16.20% | AB4: 11501 | AC4: 7416 | AD4: 3208 | AE4: 1075 | AF4: 221 | AG4: 30 | AH4: 3791 | AI4: 10580 | AJ4: 550 | AK4: 3008 | AL4: 175 | AM4: 70 | AN4: 1.26
A5: 20113 | B5: deko | C5: Denis Zhukov | D5: 21 | E5: Russia | F5: 1WIN | G5: 1WIN | H5: 8738 | I5: 6397 | J5: 36.70% | K5: 80.4 | L5: 3.4 | M5: 404 | N5: 10913 | O5: 0.8 | P5: 0.1 | Q5: 0.59 | R5: 0.09 | S5: 0.11 | T5: 5785 | U5: K - D diff. | V5: 1261 | W5: 727 | X5: 1.73 | Y5: 1.13 | Z5: 76.40% | AA5: 16.70% | AB5: 5128 | AC5: 3598 | AD5: 1549 | AE5: 518 | AF5: 112 | AG5: 8 | AH5: 2664 | AI5: 4348 | AJ5: 181 | AK5: 1459 | AL5: 86 | AM5: 40 | AN5: 1.23
A6: 18835 | B6: saffee | C6: Rafael Costa | D6: 27 | E6: Brazil | F6: FURIA | G6: FURIA, paiN | H6: 8482 | I6: 6517 | J6: 30.90% | K6: 80.2 | L6: 3 | M6: 404 | N6: 10701 | O6: 0.79 | P6: 0.1 | Q6: 0.61 | R6: 0.08 | S6: 0.1 | T6: 5488 | U6: K - D diff. | V6: 1309 | W6: 892 | X6: 1.47 | Y6: 1.14 | Z6: 76.10% | AA6: 17.30% | AB6: 5213 | AC6: 3288 | AD6: 1548 | AE6: 524 | AF6: 114 | AG6: 14 | AH6: 2545 | AI6: 4412 | AJ6: 264 | AK6: 1209 | AL6: 52 | AM6: 28 | AN6: 1.22
A7: 8950 | B7: Kaze | C7: Andrew Khong | D7: 28 | E7: Malaysia | F7: Rare Atom | G7: ViCi, Flash, MVP.karnal | H7: 17675 | I7: 13384 | J7: 30.30% | K7: 80.1 | L7: 2.9 | M7: 864 | N7: 22588 | O7: 0.78 | P7: 0.11 | Q7: 0.59 | R7: 0.08 | S7: 0.1 | T7: 11485 | U7: K - D diff. | V7: 2688 | W7: 1586 | X7: 1.69 | Y7: 1.14 | Z7: 76.50% | AA7: 17.00% | AB7: 11103 | AC7: 6900 | AD7: 3249 | AE7: 1094 | AF7: 216 | AG7: 26 | AH7: 4893 | AI7: 9053 | AJ7: 577 | AK7: 2834 | AL7: 172 | AM7: 203 | AN7: 1.19
A8: 17306 | B8: degster | C8: Abdul Gasanov | D8: 21 | E8: Russia | F8: OG | G8: Espada, Spirit | H8: 14351 | I8: 10988 | J8: 34.70% | K8: 79.3 | L8: 2.9 | M8: 686 | N8: 18284 | O8: 0.78 | P8: 0.09 | Q8: 0.6 | R8: 0.07 | S8: 0.1 | T8: 9383 | U8: K - D diff. | V8: 2480 | W8: 1469 | X8: 1.69 | Y8: 1.21 | Z8: 73.90% | AA8: 19.20% | AB8: 8901 | AC8: 5669 | AD8: 2677 | AE8: 841 | AF8: 175 | AG8: 21 | AH8: 4118 | AI8: 7544 | AJ8: 253 | AK8: 2266 | AL8: 181 | AM8: 49 | AN8: 1.21
A9: 11271 | B9: smooya | C9: Owen Butterfield | D9: 22 | E9: United Kingdom | F9: No team | G9: BIG, Movistar Riders, Epsilon | H9: 18466 | I9: 14617 | J9: 27.80% | K9: 79.3 | L9: 2.5 | M9: 888 | N9: 23515 | O9: 0.79 | P9: 0.1 | Q9: 0.62 | R9: 0.08 | S9: 0.1 | T9: 11971 | U9: K - D diff. | V9: 3187 | W9: 2183 | X9: 1.46 | Y9: 1.19 | Z9: 76.10% | AA9: 19.80% | AB9: 11544 | AC9: 7188 | AD9: 3367 | AE9: 1141 | AF9: 254 | AG9: 21 | AH9: 4786 | AI9: 9692 | AJ9: 584 | AK9: 3283 | AL9: 141 | AM9: 31 | AN9: 1.2
A10: 12591 | B10: sterling | C10: Euan Moore | D10: 24 | E10: New Zealand | F10: Encore | G10: AVANT, Looking For Org, Dire Wolves | H10: 17063 | I10: 13103 | J10: 31.60% | K10: 78.1 | L10: 4 | M10: 861 | N10: 22023 | O10: 0.77 | P10: 0.1 | Q10: 0.59 | R10: 0.08 | S10: 0.11 | T10: 11405 | U10: K - D diff. | V10: 2599 | W10: 1390 | X10: 1.87 | Y10: 1.15 | Z10: 77.70% | AA10: 17.00% | AB10: 10618 | AC10: 7146 | AD10: 3098 | AE10: 945 | AF10: 194 | AG10: 22 | AH10: 5037 | AI10: 8539 | AJ10: 437 | AK10: 2848 | AL10: 198 | AM10: 41 | AN10: 1.2
A11: 7938 | B11: XANTARES | C11: Ismailcan DÃ¶rtkardeÅŸ | D11: 26 | E11: Turkey | F11: Eternal Fire | G11: Eternal Fire, Space Soldiers, BIG | H11: 37879 | I11: 31623 | J11: 53.30% | K11: 89.1 | L11: 4.6 | M11: 1772 | N11: 46706 | O11: 0.81 | P11: 0.15 | Q11: 0.68 | R11: 0.1 | S11: 0.1 | T11: 24117 | U11: K - D diff. | V11: 6449 | W11: 5003 | X11: 1.29 | Y11: 1.18 | Z11: 74.80% | AA11: 19.40% | AB11: 22589 | AC11: 14081 | AD11: 6997 | AE11: 2414 | AF11: 564 | AG11: 61 | AH11: 30174 | AI11: 355 | AJ11: 857 | AK11: 6127 | AL11: 394 | AM11: 50 | AN11: 1.17
A12: 18227 | B12: SENSEi | C12: Dmitriy Shvorak | D12: 23 | E12: Ukraine | F12: Iron Branch | G12: CR4ZY, Project X, Akuma, Run or Die | H12: 9369 | I12: 6979 | J12: 31.30% | K12: 76.1 | L12: 2.7 | M12: 474 | N12: 12537 | O12: 0.75 | P12: 0.09 | Q12: 0.56 | R12: 0.07 | S12: 0.09 | T12: 6358 | U12: K - D diff. | V12: 1612 | W12: 812 | X12: 1.99 | Y12: 1.2 | Z12: 74.40% | AA12: 19.10% | AB12: 6179 | AC12: 4062 | AD12: 1715 | AE12: 461 | AF12: 106 | AG12: 14 | AH12: 2118 | AI12: 5533 | AJ12: 202 | AK12: 1440 | AL12: 73 | AM12: 28 | AN12: 1.21
A13: 18072 | B13: torzsi | C13: ÃdÃ¡m TorzsÃ¡s | D13: 20 | E13: Hungary | F13: MOUZ | G13: MOUZ, Budapest Five, MOUZ NXT, Salamander | H13: 9904 | I13: 7896 | J13: 29.10% | K13: 78 | L13: 2.5 | M13: 478 | N13: 12776 | O13: 0.78 | P13: 0.09 | Q13: 0.62 | R13: 0.08 | S13: 0.11 | T13: 6499 | U13: K - D diff. | V13: 1578 | W13: 1028 | X13: 1.54 | Y13: 1.15 | Z13: 76.20% | AA13: 18.30% | AB13: 6277 | AC13: 4001 | AD13: 1751 | AE13: 603 | AF13: 128 | AG13: 16 | AH13: 2352 | AI13: 5696 | AJ13: 183 | AK13: 1606 | AL13: 83 | AM13: 39 | AN13: 1.18
A14: 7592 | B14: device | C14: Nicolai Reedtz | D14: 26 | E14: Denmark | F14: NIP | G14: Astralis, TSM | H14: 36293 | I14: 29085 | J14: 35.00% | K14: 80.3 | L14: 4.3 | M14: 1793 | N14: 46666 | O14: 0.78 | P14: 0.13 | Q14: 0.62 | R14: 0.07 | S14: 0.08 | T14: 23693 | U14: K - D diff. | V14: 6207 | W14: 4437 | X14: 1.4 | Y14: 1.17 | Z14: 78.50% | AA14: 18.90% | AB14: 22973 | AC14: 14353 | AD14: 6700 | AE14: 2125 | AF14: 467 | AG14: 48 | AH14: 14483 | AI14: 12758 | AJ14: 1566 | AK14: 6978 | AL14: 431 | AM14: 121 | AN14: 1.16
A15: 16207 | B15: DANK1NG | C15: Zhenghao Lv | D15: 22 | E15: China | F15: TYLOO | G15: TYLOO, EHOME | H15: 8149 | I15: 6556 | J15: 39.70% | K15: 79.8 | L15: 2.3 | M15: 391 | N15: 10366 | O15: 0.79 | P15: 0.1 | Q15: 0.63 | R15: 0.09 | S15: 0.1 | T15: 5400 | U15: K - D diff. | V15: 1384 | W15: 921 | X15: 1.5 | Y15: 1.19 | Z15: 73.30% | AA15: 18.30% | AB15: 4966 | AC15: 3335 | AD15: 1499 | AE15: 458 | AF15: 98 | AG15: 10 | AH15: 3124 | AI15: 3177 | AJ15: 318 | AK15: 1435 | AL15: 64 | AM15: 66 | AN15: 1.2
A16: 3741 | B16: NiKo | C16: Nikola KovaÄ | D16: 25 | E16: Bosnia and Herzegovina | F16: G2 | G16: G2, FaZe, MOUZ | H16: 34634 | I16: 29087 | J16: 50.40% | K16: 86 | L16: 4.4 | M16: 1637 | N16: 43526 | O16: 0.8 | P16: 0.13 | Q16: 0.67 | R16: 0.08 | S16: 0.1 | T16: 22258 | U16: K - D diff. | V16: 6195 | W16: 5049 | X16: 1.23 | Y16: 1.18 | Z16: 73.10% | AA16: 20.00% | AB16: 21268 | AC16: 13294 | AD16: 6231 | AE16: 2146 | AF16: 519 | AG16: 68 | AH16: 23581 | AI16: 3296 | AJ16: 1138 | AK16: 6308 | AL16: 297 | AM16: 89 | AN16: 1.15
A17: 15165 | B17: blameF | C17: Benjamin Bremer | D17: 25 | E17: Denmark | F17: Astralis | G17: Astralis, Complexity, Heroic, Epsilon | H17: 18058 | I17: 14312 | J17: 39.20% | K17: 85.6 | L17: 7.1 | M17: 884 | N17: 23631 | O17: 0.76 | P17: 0.14 | Q17: 0.61 | R17: 0.07 | S17: 0.09 | T17: 12024 | U17: K - D diff. | V17: 2857 | W17: 1995 | X17: 1.43 | Y17: 1.13 | Z17: 74.10% | AA17: 17.60% | AB17: 11607 | AC17: 7531 | AD17: 3222 | AE17: 1024 | AF17: 224 | AG17: 23 | AH17: 14032 | AI17: 164 | AJ17: 827 | AK17: 2661 | AL17: 397 | AM17: 64 | AN17: 1.22
A18: 7131 | B18: BnTeT | C18: Hansel Ferdinand | D18: 26 | E18: Indonesia | F18: TYLOO | G18: TYLOO, Gen.G, EXTREMUM | H18: 20591 | I18: 16796 | J18: 39.80% | K18: 83 | L18: 5.1 | M18: 1033 | N18: 26924 | O18: 0.76 | P18: 0.14 | Q18: 0.62 | R18: 0.1 | S18: 0.12 | T18: 13454 | U18: K - D diff. | V18: 2330 | W18: 1934 | X18: 1.2 | Y18: 0.98 | Z18: 75.70% | AA18: 12.20% | AB18: 13470 | AC18: 8251 | AD18: 3628 | AE18: 1255 | AF18: 281 | AG18: 39 | AH18: 15155 | AI18: 728 | AJ18: 1169 | AK18: 3259 | AL18: 305 | AM18: 45 | AN18: 1.15
A19: 9216 | B19: coldzera | C19: Marcelo David | D19: 27 | E19: Brazil | F19: 00NATION | G19: SK, FaZe, Luminosity, MIBR | H19: 28576 | I19: 22946 | J19: 49.40% | K19: 79.2 | L19: 2.4 | M19: 1426 | N19: 37264 | O19: 0.77 | P19: 0.11 | Q19: 0.62 | R19: 0.08 | S19: 0.1 | T19: 19016 | U19: K - D diff. | V19: 3355 | W19: 2453 | X19: 1.37 | Y19: 1.01 | Z19: 74.90% | AA19: 12.50% | AB19: 18248 | AC19: 11854 | AD19: 5167 | AE19: 1623 | AF19: 341 | AG19: 31 | AH19: 17732 | AI19: 3229 | AJ19: 2161 | AK19: 5249 | AL19: 205 | AM19: 60 | AN19: 1.15
A20: 9102 | B20: Sico | C20: Simon Williams | D20: 27 | E20: New Zealand | F20: ORDER | G20: ORDER, Renegades, Grayhound, Kings | H20: 17188 | I20: 13437 | J20: 35.40% | K20: 79.1 | L20: 6.9 | M20: 902 | N20: 22858 | O20: 0.75 | P20: 0.14 | Q20: 0.59 | R20: 0.09 | S20: 0.1 | T20: 11611 | U20: K - D diff. | V20: 2600 | W20: 1399 | X20: 1.86 | Y20: 1.13 | Z20: 80.90% | AA20: 16.10% | AB20: 11247 | AC20: 7366 | AD20: 3111 | AE20: 954 | AF20: 162 | AG20: 18 | AH20: 5220 | AI20: 7131 | AJ20: 982 | AK20: 3423 | AL20: 439 | AM20: 29 | AN20: 1.15
A21: 9172 | B21: XigN | C21: Hyun-Pyo Lee | D21: 25 | E21: Korea | F21: NKT | G21: NKT, MVP PK, MVP Project | H21: 14756 | I21: 12329 | J21: 52.40% | K21: 82.6 | L21: 2.8 | M21: 727 | N21: 18859 | O21: 0.78 | P21: 0.12 | Q21: 0.65 | R21: 0.09 | S21: 0.1 | T21: 9608 | U21: K - D diff. | V21: 2189 | W21: 1915 | X21: 1.14 | Y21: 1.08 | Z21: 72.40% | AA21: 15.70% | AB21: 9251 | AC21: 5822 | AD21: 2662 | AE21: 912 | AF21: 186 | AG21: 26 | AH21: 10598 | AI21: 371 | AJ21: 1087 | AK21: 2569 | AL21: 113 | AM21: 47 | AN21: 1.14
A22: 15631 | B22: KSCERATO | C22: Kaike Cerato | D22: 22 | E22: Brazil | F22: FURIA | G22: FURIA | H22: 17821 | I22: 14059 | J22: 49.40% | K22: 79.2 | L22: 5.4 | M22: 930 | N22: 24208 | O22: 0.74 | P22: 0.13 | Q22: 0.58 | R22: 0.08 | S22: 0.1 | T22: 11907 | U22: K - D diff. | V22: 2047 | W22: 1497 | X22: 1.37 | Y22: 0.99 | Z22: 75.00% | AA22: 11.70% | AB22: 12301 | AC22: 7473 | AD22: 3205 | AE22: 1006 | AF22: 195 | AG22: 28 | AH22: 12854 | AI22: 551 | AJ22: 1355 | AK22: 2739 | AL22: 326 | AM22: 101 | AN22: 1.18
A23: 8944 | B23: Benkai | C23: Benedict Tan | D23: 25 | E23: Singapore | F23: No team | G23: BOOT-d[S], BOOT, dream[S]cape | H23: 12164 | I23: 10118 | J23: 46.70% | K23: 85.4 | L23: 4.2 | M23: 603 | N23: 15560 | O23: 0.78 | P23: 0.14 | Q23: 0.65 | R23: 0.07 | S23: 0.1 | T23: 7983 | U23: K - D diff. | V23: 1838 | W23: 1550 | X23: 1.19 | Y23: 1.09 | Z23: 75.80% | AA23: 17.00% | AB23: 7577 | AC23: 4863 | AD23: 2231 | AE23: 732 | AF23: 142 | AG23: 15 | AH23: 8704 | AI23: 427 | AJ23: 826 | AK23: 1973 | AL23: 157 | AM23: 101 | AN23: 1.14
A24: 11847 | B24: Texta | C24: Matthew O'Rourke | D24: 21 | E24: Australia | F24: No team | G24: Chiefs, Athletico, Dark Sided | H24: 12510 | I24: 10760 | J24: 40.30% | K24: 87.1 | L24: 3.6 | M24: 625 | N24: 15713 | O24: 0.8 | P24: 0.18 | Q24: 0.68 | R24: 0.1 | S24: 0.13 | T24: 8125 | U24: K - D diff. | V24: 1908 | W24: 1825 | X24: 1.05 | Y24: 1.08 | Z24: 75.80% | AA24: 16.90% | AB24: 7588 | AC24: 4887 | AD24: 2284 | AE24: 775 | AF24: 165 | AG24: 14 | AH24: 9814 | AI24: 148 | AJ24: 264 | AK24: 2192 | AL24: 109 | AM24: 6 | AN24: 1.21
A25: 13776 | B25: Jame | C25: Dzhami Ali | D25: 23 | E25: Russia | F25: Outsiders | G25: AVANGAR, Virtus.pro | H25: 22608 | I25: 17316 | J25: 25.20% | K25: 73 | L25: 3.9 | M25: 1189 | N25: 31521 | O25: 0.72 | P25: 0.09 | Q25: 0.55 | R25: 0.07 | S25: 0.09 | T25: 15469 | U25: K - D diff. | V25: 3753 | W25: 2089 | X25: 1.8 | Y25: 1.15 | Z25: 76.00% | AA25: 17.10% | AB25: 16052 | AC25: 10001 | AD25: 4041 | AE25: 1202 | AF25: 206 | AG25: 19 | AH25: 3061 | AI25: 14965 | AJ25: 1081 | AK25: 3198 | AL25: 252 | AM25: 137 | AN25: 1.17
A26: 9626 | B26: XELLOW | C26: Adrian GuÈ›Äƒ | D26: 21 | E26: Romania | F26: ECSTATIC | G26: Nexus | H26: 22423 | I26: 19052 | J26: 40.40% | K26: 80 | L26: 1.8 | M26: 1097 | N26: 28850 | O26: 0.78 | P26: 0.11 | Q26: 0.66 | R26: 0.09 | S26: 0.11 | T26: 14611 | U26: K - D diff. | V26: 3983 | W26: 2960 | X26: 1.35 | Y26: 1.19 | Z26: 73.40% | AA26: 19.80% | AB26: 14239 | AC26: 8851 | AD26: 4086 | AE26: 1327 | AF26: 316 | AG26: 31 | AH26: 8583 | AI26: 9211 | AJ26: 507 | AK26: 3998 | AL26: 133 | AM26: 50 | AN26: 1.13
A27: 16847 | B27: mhL | C27: MiÅ‚osz Knasiak | D27: 20 | E27: Poland | F27: MOUZ NXT | G27: MOUZ NXT, AGO | H27: 10241 | I27: 8484 | J27: 28.50% | K27: 80 | L27: 3.8 | M27: 498 | N27: 13378 | O27: 0.77 | P27: 0.12 | Q27: 0.63 | R27: 0.1 | S27: 0.11 | T27: 6773 | U27: K - D diff. | V27: 1656 | W27: 1114 | X27: 1.49 | Y27: 1.15 | Z27: 76.70% | AA27: 18.40% | AB27: 6605 | AC27: 4156 | AD27: 1896 | AE27: 596 | AF27: 120 | AG27: 5 | AH27: 2444 | AI27: 5801 | AJ27: 181 | AK27: 1687 | AL27: 153 | AM27: 16 | AN27: 1.17
A28: 798 | B28: oskar | C28: TomÃ¡Å¡ Å Å¥astnÃ½ | D28: 31 | E28: Czech Republic | F28: Tokyo Revengers | G28: MOUZ, SINNERS, HellRaisers | H28: 29371 | I28: 24509 | J28: 30.50% | K28: 78.2 | L28: 3.4 | M28: 1460 | N28: 38504 | O28: 0.76 | P28: 0.1 | Q28: 0.64 | R28: 0.07 | S28: 0.08 | T28: 19306 | U28: K - D diff. | V28: 5123 | W28: 3652 | X28: 1.4 | Y28: 1.17 | Z28: 73.40% | AA28: 18.90% | AB28: 19198 | AC28: 11802 | AD28: 5377 | AE28: 1731 | AF28: 363 | AG28: 33 | AH28: 5625 | AI28: 16854 | AJ28: 1023 | AK28: 5191 | AL28: 335 | AM28: 406 | AN28: 1.13
A29: 13281 | B29: El1an | C29: Aleksei Gusev | D29: 23 | E29: Russia | F29: Entropiq | G29: Entropiq, Winstrike, EPG | H29: 26132 | I29: 21336 | J29: 27.10% | K29: 78.1 | L29: 2.7 | M29: 1304 | N29: 34783 | O29: 0.75 | P29: 0.11 | Q29: 0.61 | R29: 0.07 | S29: 0.08 | T29: 17472 | U29: K - D diff. | V29: 4718 | W29: 2938 | X29: 1.61 | Y29: 1.2 | Z29: 74.50% | AA29: 19.70% | AB29: 17311 | AC29: 10958 | AD29: 4691 | AE29: 1525 | AF29: 273 | AG29: 25 | AH29: 5031 | AI29: 16248 | AJ29: 396 | AK29: 4164 | AL29: 233 | AM29: 122 | AN29: 1.17
A30: 7167 | B30: kennyS | C30: Kenny Schrub | D30: 27 | E30: France | F30: G2 | G30: G2, Envy, Titan | H30: 37067 | I30: 30736 | J30: 31.20% | K30: 74.7 | L30: 3.4 | M30: 1852 | N30: 48898 | O30: 0.76 | P30: 0.11 | Q30: 0.63 | R30: 0.09 | S30: 0.11 | T30: 24567 | U30: K - D diff. | V30: 5847 | W30: 3969 | X30: 1.47 | Y30: 1.13 | Z30: 76.50% | AA30: 17.50% | AB30: 24331 | AC30: 15241 | AD30: 6747 | AE30: 2120 | AF30: 412 | AG30: 47 | AH30: 8533 | AI30: 19544 | AJ30: 843 | AK30: 7423 | AL30: 707 | AM30: 80 | AN30: 1.13
A31: 10774 | B31: Freeman | C31: WingHei Cheung | D31: 23 | E31: Hong Kong | F31: YK | G31: ViCi, TYLOO | H31: 15040 | I31: 12743 | J31: 49.10% | K31: 80.7 | L31: 2.9 | M31: 773 | N31: 19766 | O31: 0.76 | P31: 0.13 | Q31: 0.64 | R31: 0.09 | S31: 0.11 | T31: 9837 | U31: K - D diff. | V31: 1902 | W31: 1717 | X31: 1.11 | Y31: 1 | Z31: 75.70% | AA31: 13.50% | AB31: 9929 | AC31: 5988 | AD31: 2725 | AE31: 918 | AF31: 182 | AG31: 24 | AH31: 10686 | AI31: 690 | AJ31: 766 | AK31: 2735 | AL31: 158 | AM31: 32 | AN31: 1.16
A32: 10981 | B32: mantuu | C32: Mateusz Wilczewski | D32: 24 | E32: Poland | F32: No team | G32: OG, ALTERNATE aTTaX, PANTHERS | H32: 13904 | I32: 11530 | J32: 35.70% | K32: 76.7 | L32: 3.4 | M32: 696 | N32: 18646 | O32: 0.75 | P32: 0.11 | Q32: 0.62 | R32: 0.09 | S32: 0.12 | T32: 9247 | U32: K - D diff. | V32: 2203 | W32: 1553 | X32: 1.42 | Y32: 1.12 | Z32: 73.40% | AA32: 17.30% | AB32: 9399 | AC32: 5767 | AD32: 2516 | AE32: 774 | AF32: 167 | AG32: 23 | AH32: 5626 | AI32: 5438 | AJ32: 448 | AK32: 2252 | AL32: 151 | AM32: 31 | AN32: 1.16
A33: 3972 | B33: huNter- | C33: Nemanja KovaÄ | D33: 26 | E33: Bosnia and Herzegovina | F33: G2 | G33: G2, Valiance, Binary Dragons | H33: 30144 | I33: 25923 | J33: 49.40% | K33: 84.8 | L33: 5.5 | M33: 1474 | N33: 38947 | O33: 0.77 | P33: 0.14 | Q33: 0.67 | R33: 0.1 | S33: 0.11 | T33: 19652 | U33: K - D diff. | V33: 4536 | W33: 3818 | X33: 1.19 | Y33: 1.09 | Z33: 76.10% | AA33: 16.60% | AB33: 19295 | AC33: 11861 | AD33: 5534 | AE33: 1846 | AF33: 378 | AG33: 33 | AH33: 21272 | AI33: 344 | AJ33: 3190 | AK33: 4826 | AL33: 422 | AM33: 156 | AN33: 1.12
A34: 9960 | B34: frozen | C34: David ÄŒerÅˆanskÃ½ | D34: 20 | E34: Slovakia | F34: MOUZ | G34: MOUZ, eXtatus | H34: 24136 | I34: 20574 | J34: 54.60% | K34: 82.9 | L34: 5.1 | M34: 1218 | N34: 31866 | O34: 0.76 | P34: 0.13 | Q34: 0.65 | R34: 0.09 | S34: 0.11 | T34: 15834 | U34: K - D diff. | V34: 3463 | W34: 3098 | X34: 1.12 | Y34: 1.05 | Z34: 73.50% | AA34: 15.10% | AB34: 16032 | AC34: 9799 | AD34: 4184 | AE34: 1471 | AF34: 344 | AG34: 36 | AH34: 17384 | AI34: 1178 | AJ34: 849 | AK34: 4379 | AL34: 333 | AM34: 100 | AN34: 1.12
A35: 16816 | B35: vsm | C35: Vinicius Moreira | D35: 23 | E35: Brazil | F35: 00NATION | G35: DETONA, 00NATION | H35: 10883 | I35: 9398 | J35: 47.00% | K35: 83.6 | L35: 3.1 | M35: 533 | N35: 14130 | O35: 0.77 | P35: 0.13 | Q35: 0.67 | R35: 0.09 | S35: 0.1 | T35: 7098 | U35: K - D diff. | V35: 1806 | W35: 1548 | X35: 1.17 | Y35: 1.12 | Z35: 73.20% | AA35: 17.90% | AB35: 7032 | AC35: 4315 | AD35: 1963 | AE35: 647 | AF35: 164 | AG35: 9 | AH35: 7544 | AI35: 1047 | AJ35: 404 | AK35: 1800 | AL35: 99 | AM35: 32 | AN35: 1.18
A36: 12877 | B36: chelleos | C36: Michael Hawkins | D36: 22 | E36: New Zealand | F36: No team | G36: Rooster, madlikewizards, Paradox | H36: 11270 | I36: 9818 | J36: 32.00% | K36: 84.2 | L36: 4.1 | M36: 560 | N36: 14454 | O36: 0.78 | P36: 0.13 | Q36: 0.68 | R36: 0.1 | S36: 0.09 | T36: 7347 | U36: K - D diff. | V36: 2574 | W36: 2036 | X36: 1.26 | Y36: 1.32 | Z36: 72.30% | AA36: 24.80% | AB36: 7107 | AC36: 4471 | AD36: 2021 | AE36: 679 | AF36: 160 | AG36: 16 | AH36: 3548 | AI36: 5692 | AJ36: 260 | AK36: 1601 | AL36: 160 | AM36: 35 | AN36: 1.2
A37: 11141 | B37: erkaSt | C37: Erdenetsogt Gantulga | D37: 27 | E37: Mongolia | F37: NKT | G37: Grayhound, TIGER, Immunity | H37: 17397 | I37: 14889 | J37: 50.10% | K37: 83.3 | L37: 5.1 | M37: 869 | N37: 22571 | O37: 0.77 | P37: 0.15 | Q37: 0.66 | R37: 0.09 | S37: 0.09 | T37: 11431 | U37: K - D diff. | V37: 2385 | W37: 2041 | X37: 1.17 | Y37: 1.04 | Z37: 75.20% | AA37: 14.30% | AB37: 11140 | AC37: 6979 | AD37: 3187 | AE37: 1032 | AF37: 217 | AG37: 16 | AH37: 12309 | AI37: 384 | AJ37: 1608 | AK37: 2838 | AL37: 247 | AM37: 52 | AN37: 1.17
A38: 12553 | B38: yuurih | C38: Yuri Santos | D38: 22 | E38: Brazil | F38: FURIA | G38: FURIA | H38: 20149 | I38: 16995 | J38: 44.30% | K38: 84.2 | L38: 5 | M38: 1022 | N38: 26677 | O38: 0.76 | P38: 0.15 | Q38: 0.64 | R38: 0.09 | S38: 0.11 | T38: 13336 | U38: K - D diff. | V38: 2580 | W38: 1877 | X38: 1.37 | Y38: 1.03 | Z38: 76.40% | AA38: 13.70% | AB38: 13341 | AC38: 8292 | AD38: 3570 | AE38: 1201 | AF38: 251 | AG38: 22 | AH38: 15471 | AI38: 453 | AJ38: 744 | AK38: 3219 | AL38: 286 | AM38: 43 | AN38: 1.18
A39: 8574 | B39: woxic | C39: Ã–zgÃ¼r Eker | D39: 23 | E39: Turkey | F39: Eternal Fire | G39: Eternal Fire, HellRaisers, MOUZ, DarkPassage | H39: 22815 | I39: 18947 | J39: 32.10% | K39: 76.4 | L39: 2.4 | M39: 1178 | N39: 30952 | O39: 0.74 | P39: 0.11 | Q39: 0.61 | R39: 0.08 | S39: 0.1 | T39: 15130 | U39: K - D diff. | V39: 3693 | W39: 2485 | X39: 1.49 | Y39: 1.13 | Z39: 76.10% | AA39: 17.30% | AB39: 15822 | AC39: 9398 | AD39: 4130 | AE39: 1287 | AF39: 279 | AG39: 36 | AH39: 6232 | AI39: 12438 | AJ39: 462 | AK39: 3472 | AL39: 214 | AM39: 84 | AN39: 1.12
A40: 1088 | B40: liTTle | C40: Anatoliy Yashin | D40: 33 | E40: Russia | F40: HellRaisers | G40: forZe, RuSh3D, Spartak, Enso | H40: 9317 | I40: 7766 | J40: 27.70% | K40: 78.5 | L40: 2.6 | M40: 457 | N40: 12154 | O40: 0.77 | P40: 0.1 | Q40: 0.64 | R40: 0.07 | S40: 0.09 | T40: 6279 | U40: K - D diff. | V40: 1595 | W40: 1041 | X40: 1.53 | Y40: 1.18 | Z40: 71.60% | AA40: 19.00% | AB40: 5875 | AC40: 3952 | AD40: 1735 | AE40: 484 | AF40: 99 | AG40: 9 | AH40: 1248 | AI40: 5656 | AJ40: 105 | AK40: 2206 | AL40: 112 | AM40: 7 | AN40: 1.12
...

Sheet Dataset_Csplayers
A1: player_id | B1: nickname | C1: real_name | D1: age | E1: country | F1: current_team | G1: teams | H1: total_kills | I1: total_deaths | J1: headshot_percentage | K1: damage_per_round | L1: grenade_dmg_per_round | M1: maps_played | N1: rounds_played | O1: kills_per_round | P1: assists_per_round | Q1: deaths_per_round | R1: saved_by_teammate_per_round | S1: saved_teammates_per_round | T1: rounds_with_kills | U1: kill_to_death_diff | V1: total_opening_kills | W1: total_opening_deaths | X1: opening_kill_ratio | Y1: opening_kill_rating | Z1: team_win_percent_after_first_kill | AA1: first_kill_in_won_rounds | AB1: 0_kill_rounds | AC1: 1_kill_rounds | AD1: 2_kill_rounds | AE1: 3_kill_rounds | AF1: 4_kill_rounds | AG1: 5_kill_rounds | AH1: rifle_kills | AI1: sniper_kills | AJ1: smg_kills | AK1: pistol_kills | AL1: grenade_kills | AM1: other_kills | AN1: rating | AO1: KPI | AP1: Segmentacion | AS1: Intervalo
A2: 8346 | B2: jdm64 | C2: Josh Marzano | D2: 32 | E2: United States | F2: No team | G2: Liquid, CLG, Envy | H2: 14626 | I2: 13801 | J2: 23.60% | K2: 70.1 | L2: 2.9 | M2: 823 | N2: 21321 | O2: 0.69 | P2: 0.1 | Q2: 0.65 | R2: 0.1 | S2: 0.09 | T2: 9980 | U2: K - D diff. | V2: 2613 | W2: 1953 | X2: 1.34 | Y2: 1.13 | Z2: 74.30% | AA2: 17.90% | AB2: 11341 | AC2: 6437 | AD2: 2625 | AE2: 757 | AF2: 147 | AG2: 14 | AH2: 1539 | AI2: 9275 | AJ2: 1024 | AK2: 2645 | AL2: 146 | AM2: 19 | AN2: 1.02 | AO2: =AVERAGE(Tabla2[[#This Row],[total_kills]:[rating]]) -> 5320.3158 | AP2: =VLOOKUP(Tabla2[[#This Row],[KPI]],$AS$2:$AT$5,2,1) -> Alto | AS2: =MIN(AO:AO) -> 2253.55 | AT2: Bajo
A3: 7440 | B3: Skadoodle | C3: Tyler Latham | D3: 29 | E3: United States | F3: No team | G3: Cloud9 | H3: 18365 | I3: 15907 | J3: 24.80% | K3: 67.5 | L3: 2.7 | M3: 1047 | N3: 27129 | O3: 0.68 | P3: 0.11 | Q3: 0.59 | R3: 0.09 | S3: 0.09 | T3: 12658 | U3: K - D diff. | V3: 2832 | W3: 1829 | X3: 1.55 | Y3: 1.08 | Z3: 76.90% | AA3: 14.80% | AB3: 14471 | AC3: 8308 | AD3: 3226 | AE3: 931 | AF3: 172 | AG3: 21 | AH3: 3839 | AI3: 10111 | AJ3: 563 | AK3: 3592 | AL3: 238 | AM3: 44 | AN3: 1.06 | AO3: =AVERAGE(Tabla2[[#This Row],[total_kills]:[rating]]) -> 6593.8421 | AP3: =VLOOKUP(Tabla2[[#This Row],[KPI]],$AS$2:$AT$5,2,1) -> Alto | AS3: =QUARTILE(AO:AO,1) -> 3297.4684 | AT3: Medio
A4: 12733 | B4: xsepower | C4: Bogdan Chernikov | D4: 24 | E4: Russia | F4: K23 | G4: K23, forZe | H4: 24769 | I4: 20066 | J4: 24.90% | K4: 72.4 | L4: 2.2 | M4: 1282 | N4: 34452 | O4: 0.72 | P4: 0.08 | Q4: 0.58 | R4: 0.07 | S4: 0.08 | T4: 16798 | U4: K - D diff. | V4: 5002 | W4: 3073 | X4: 1.63 | Y4: 1.24 | Z4: 74.90% | AA4: 20.80% | AB4: 17654 | AC4: 10662 | AD4: 4559 | AE4: 1337 | AF4: 222 | AG4: 18 | AH4: 2339 | AI4: 17549 | AJ4: 825 | AK4: 3919 | AL4: 175 | AM4: 47 | AN4: 1.15 | AO4: =AVERAGE(Tabla2[[#This Row],[total_kills]:[rating]]) -> 8670.9474 | AP4: =VLOOKUP(Tabla2[[#This Row],[KPI]],$AS$2:$AT$5,2,1) -> Superior | AS4: =MEDIAN(AO:AO) -> 4807.5263 | AT4: Alto
A5: 10992 | B5: dragonfly | C5: Jacob Lund | D5: 25 | E5: Denmark | F5: ex-Maknitude | G5: Fragsters | H5: 9094 | I5: 8592 | J5: 25.10% | K5: 70.8 | L5: 3.1 | M5: 507 | N5: 13234 | O5: 0.69 | P5: 0.09 | Q5: 0.65 | R5: 0.09 | S5: 0.08 | T5: 6202 | U5: K - D diff. | V5: 1848 | W5: 1376 | X5: 1.34 | Y5: 1.19 | Z5: 75.60% | AA5: 20.80% | AB5: 7032 | AC5: 3997 | AD5: 1630 | AE5: 472 | AF5: 94 | AG5: 9 | AH5: 1259 | AI5: 5965 | AJ5: 379 | AK5: 1375 | AL5: 120 | AM5: 13 | AN5: 1.06 | AO5: =AVERAGE(Tabla2[[#This Row],[total_kills]:[rating]]) -> 3326.2105 | AP5: =VLOOKUP(Tabla2[[#This Row],[KPI]],$AS$2:$AT$5,2,1) -> Medio | AS5: =QUARTILE(AO:AO,3) -> 6902.5526 | AT5: Superior
A6: 13776 | B6: Jame | C6: Dzhami Ali | D6: 23 | E6: Russia | F6: Outsiders | G6: AVANGAR, Virtus.pro | H6: 22608 | I6: 17316 | J6: 25.20% | K6: 73 | L6: 3.9 | M6: 1189 | N6: 31521 | O6: 0.72 | P6: 0.09 | Q6: 0.55 | R6: 0.07 | S6: 0.09 | T6: 15469 | U6: K - D diff. | V6: 3753 | W6: 2089 | X6: 1.8 | Y6: 1.15 | Z6: 76.00% | AA6: 17.10% | AB6: 16052 | AC6: 10001 | AD6: 4041 | AE6: 1202 | AF6: 206 | AG6: 19 | AH6: 3061 | AI6: 14965 | AJ6: 1081 | AK6: 3198 | AL6: 252 | AM6: 137 | AN6: 1.17 | AO6: =AVERAGE(Tabla2[[#This Row],[total_kills]:[rating]]) -> 7411.65 | AP6: =VLOOKUP(Tabla2[[#This Row],[KPI]],$AS$2:$AT$5,2,1) -> Superior | AS6: =MAX(AO:AO) -> 14155.526
A7: 15255 | B7: Swahn | C7: Christopher Swahn | D7: 24 | E7: United States | F7: No team | G7: iNTACT, Bad News Bears, Detonate, Bushido Boyz | H7: 7290 | I7: 6722 | J7: 25.70% | K7: 72.5 | L7: 3.5 | M7: 397 | N7: 10421 | O7: 0.7 | P7: 0.1 | Q7: 0.65 | R7: 0.1 | S7: 0.1 | T7: 4937 | U7: K - D diff. | V7: 1221 | W7: 916 | X7: 1.33 | Y7: 1.11 | Z7: 73.20% | AA7: 18.00% | AB7: 5484 | AC7: 3148 | AD7: 1311 | AE7: 402 | AF7: 66 | AG7: 10 | AH7: 1161 | AI7: 4695 | AJ7: 184 | AK7: 1124 | AL7: 102 | AM7: 49 | AN7: 1.08 | AO7: =AVERAGE(Tabla2[[#This Row],[total_kills]:[rating]]) -> 2612.6316 | AP7: =VLOOKUP(Tabla2[[#This Row],[KPI]],$AS$2:$AT$5,2,1) -> Bajo
A8: 8707 | B8: ptr | C8: Peter Gurney | D8: 32 | E8: United States | F8: No team | G8: Bad News Bears, NRG, Complexity | H8: 20902 | I8: 18205 | J8: 26.00% | K8: 73.3 | L8: 3.4 | M8: 1132 | N8: 29624 | O8: 0.71 | P8: 0.11 | Q8: 0.61 | R8: 0.09 | S8: 0.1 | T8: 14117 | U8: K - D diff. | V8: 3363 | W8: 2286 | X8: 1.47 | Y8: 1.11 | Z8: 74.90% | AA8: 16.30% | AB8: 15507 | AC8: 8983 | AD8: 3752 | AE8: 1149 | AF8: 210 | AG8: 23 | AH8: 3177 | AI8: 12210 | AJ8: 1214 | AK8: 4103 | AL8: 185 | AM8: 55 | AN8: 1.07 | AO8: =AVERAGE(Tabla2[[#This Row],[total_kills]:[rating]]) -> 7378.7895 | AP8: =VLOOKUP(Tabla2[[#This Row],[KPI]],$AS$2:$AT$5,2,1) -> Superior
A9: 7413 | B9: Nico | C9: Nicolaj Jensen | D9: 30 | E9: Denmark | F9: No team | G9: Dignitas, CPH Wolves, Western Wolves | H9: 6738 | I9: 6191 | J9: 26.00% | K9: 80.6 | L9: 4.9 | M9: 399 | N9: 10074 | O9: 0.67 | P9: 0.12 | Q9: 0.61 | R9: 0.08 | S9: 0.14 | T9: 4644 | U9: K - D diff. | V9: 1165 | W9: 898 | X9: 1.3 | Y9: 1.1 | Z9: 76.40% | AA9: 16.80% | AB9: 5430 | AC9: 3033 | AD9: 1220 | AE9: 334 | AF9: 53 | AG9: 4 | AH9: 1314 | AI9: 3589 | AJ9: 119 | AK9: 1561 | AL9: 143 | AM9: 12 | AN9: 1.02 | AO9: =AVERAGE(Tabla2[[#This Row],[total_kills]:[rating]]) -> 2469.5263 | AP9: =VLOOKUP(Tabla2[[#This Row],[KPI]],$AS$2:$AT$5,2,1) -> Bajo
A10: 12699 | B10: STOMP | C10: Daniel PÅ‚omiÅ„ski | D10: 27 | E10: Poland | F10: No team | G10: x-kom, Izako Boars, Illuminar, HONORIS | H10: 15139 | I10: 13810 | J10: 26.10% | K10: 73.3 | L10: 3.9 | M10: 809 | N10: 21729 | O10: 0.7 | P10: 0.11 | Q10: 0.64 | R10: 0.08 | S10: 0.09 | T10: 10363 | U10: K - D diff. | V10: 2654 | W10: 2035 | X10: 1.3 | Y10: 1.12 | Z10: 73.70% | AA10: 18.10% | AB10: 11366 | AC10: 6696 | AD10: 2735 | AE10: 766 | AF10: 155 | AG10: 11 | AH10: 2551 | AI10: 9550 | AJ10: 371 | AK10: 2422 | AL10: 221 | AM10: 73 | AN10: 1.09 | AO10: =AVERAGE(Tabla2[[#This Row],[total_kills]:[rating]]) -> 5445.0526 | AP10: =VLOOKUP(Tabla2[[#This Row],[KPI]],$AS$2:$AT$5,2,1) -> Alto
A11: 7 | B11: Friis | C11: Michael JÃ¸rgensen | D11: 33 | E11: Denmark | F11: No team | G11: SK, fnatic, Heroic, Tricked | H11: 16356 | I11: 15609 | J11: 26.30% | K11: 69.4 | L11: 2.4 | M11: 938 | N11: 24254 | O11: 0.67 | P11: 0.11 | Q11: 0.64 | R11: 0.09 | S11: 0.08 | T11: 11183 | U11: K - D diff. | V11: 2869 | W11: 2320 | X11: 1.24 | Y11: 1.1 | Z11: 77.60% | AA11: 17.80% | AB11: 13071 | AC11: 7197 | AD11: 2987 | AE11: 852 | AF11: 139 | AG11: 8 | AH11: 3259 | AI11: 9150 | AJ11: 659 | AK11: 3027 | AL11: 242 | AM11: 29 | AN11: 1.01 | AO11: =AVERAGE(Tabla2[[#This Row],[total_kills]:[rating]]) -> 6007.8421 | AP11: =VLOOKUP(Tabla2[[#This Row],[KPI]],$AS$2:$AT$5,2,1) -> Alto
A12: 8724 | B12: 1uke | C12: Aleksey Zimin | D12: 29 | E12: Russia | F12: No team | G12: Spirit Academy, HOLLYWOOD, PLINK | H12: 11017 | I12: 10794 | J12: 26.40% | K12: 71.6 | L12: 2.2 | M12: 623 | N12: 16179 | O12: 0.68 | P12: 0.09 | Q12: 0.67 | R12: 0.08 | S12: 0.07 | T12: 7466 | U12: K - D diff. | V12: 2247 | W12: 1858 | X12: 1.21 | Y12: 1.17 | Z12: 73.30% | AA12: 20.70% | AB12: 8713 | AC12: 4715 | AD12: 2072 | AE12: 569 | AF12: 99 | AG12: 11 | AH12: 1576 | AI12: 7031 | AJ12: 601 | AK12: 1708 | AL12: 90 | AM12: 23 | AN12: 1 | AO12: =AVERAGE(Tabla2[[#This Row],[total_kills]:[rating]]) -> 3869.65 | AP12: =VLOOKUP(Tabla2[[#This Row],[KPI]],$AS$2:$AT$5,2,1) -> Medio
A13: 11283 | B13: ottoNd | C13: Otto Sihvo | D13: 24 | E13: Finland | F13: HAVU | G13: HAVU, Valiance, CR4ZY, c0ntact | H13: 16712 | I13: 14070 | J13: 26.90% | K13: 76.2 | L13: 3.3 | M13: 855 | N13: 22591 | O13: 0.74 | P13: 0.1 | Q13: 0.62 | R13: 0.09 | S13: 0.11 | T13: 11142 | U13: K - D diff. | V13: 2836 | W13: 1902 | X13: 1.49 | Y13: 1.15 | Z13: 75.50% | AA13: 18.00% | AB13: 11449 | AC13: 6904 | AD13: 3104 | AE13: 955 | AF13: 160 | AG13: 19 | AH13: 3782 | AI13: 9345 | AJ13: 556 | AK13: 2879 | AL13: 170 | AM13: 13 | AN13: 1.15 | AO13: =AVERAGE(Tabla2[[#This Row],[total_kills]:[rating]]) -> 5760.2105 | AP13: =VLOOKUP(Tabla2[[#This Row],[KPI]],$AS$2:$AT$5,2,1) -> Alto
A14: 14273 | B14: iDISBALANCE | C14: Artem Egorov | D14: 25 | E14: Russia | F14: Nemiga | G14: Nemiga, Spirit | H14: 16525 | I14: 14435 | J14: 27.00% | K14: 74.1 | L14: 2.5 | M14: 871 | N14: 23106 | O14: 0.72 | P14: 0.1 | Q14: 0.62 | R14: 0.09 | S14: 0.09 | T14: 11262 | U14: K - D diff. | V14: 2996 | W14: 1938 | X14: 1.55 | Y14: 1.18 | Z14: 74.70% | AA14: 18.90% | AB14: 11844 | AC14: 7233 | AD14: 2975 | AE14: 893 | AF14: 142 | AG14: 19 | AH14: 3811 | AI14: 9648 | AJ14: 323 | AK14: 2619 | AL14: 126 | AM14: 45 | AN14: 1.13 | AO14: =AVERAGE(Tabla2[[#This Row],[total_kills]:[rating]]) -> 5832.1579 | AP14: =VLOOKUP(Tabla2[[#This Row],[KPI]],$AS$2:$AT$5,2,1) -> Alto
A15: 13281 | B15: El1an | C15: Aleksei Gusev | D15: 23 | E15: Russia | F15: Entropiq | G15: Entropiq, Winstrike, EPG | H15: 26132 | I15: 21336 | J15: 27.10% | K15: 78.1 | L15: 2.7 | M15: 1304 | N15: 34783 | O15: 0.75 | P15: 0.11 | Q15: 0.61 | R15: 0.07 | S15: 0.08 | T15: 17472 | U15: K - D diff. | V15: 4718 | W15: 2938 | X15: 1.61 | Y15: 1.2 | Z15: 74.50% | AA15: 19.70% | AB15: 17311 | AC15: 10958 | AD15: 4691 | AE15: 1525 | AF15: 273 | AG15: 25 | AH15: 5031 | AI15: 16248 | AJ15: 396 | AK15: 4164 | AL15: 233 | AM15: 122 | AN15: 1.17 | AO15: =AVERAGE(Tabla2[[#This Row],[total_kills]:[rating]]) -> 8929.4737 | AP15: =VLOOKUP(Tabla2[[#This Row],[KPI]],$AS$2:$AT$5,2,1) -> Superior
A16: 9008 | B16: FANAT ROCKA | C16: Vasiliy Trusov | D16: 30 | E16: Russia | F16: VRTX | G16: Unique, Quantum Bellator Fire, Space Jam | H16: 8262 | I16: 7809 | J16: 27.10% | K16: 71.8 | L16: 2.8 | M16: 465 | N16: 12150 | O16: 0.68 | P16: 0.11 | Q16: 0.64 | R16: 0.08 | S16: 0.09 | T16: 5628 | U16: K - D diff. | V16: 1422 | W16: 1108 | X16: 1.28 | Y16: 1.1 | Z16: 74.50% | AA16: 17.90% | AB16: 6522 | AC16: 3630 | AD16: 1471 | AE16: 430 | AF16: 87 | AG16: 10 | AH16: 1655 | AI16: 4582 | AJ16: 182 | AK16: 1730 | AL16: 101 | AM16: 31 | AN16: 1.02 | AO16: =AVERAGE(Tabla2[[#This Row],[total_kills]:[rating]]) -> 3014.4737 | AP16: =VLOOKUP(Tabla2[[#This Row],[KPI]],$AS$2:$AT$5,2,1) -> Bajo
A17: 8727 | B17: waterfaLLZ | C17: Nikita Matveyev | D17: 27 | E17: Russia | F17: No team | G17: Quantum Bellator Fire, PiTER, AVE, EPG | H17: 16371 | I17: 16030 | J17: 27.10% | K17: 72.5 | L17: 3.2 | M17: 899 | N17: 23842 | O17: 0.69 | P17: 0.12 | Q17: 0.67 | R17: 0.09 | S17: 0.08 | T17: 11101 | U17: K - D diff. | V17: 2854 | W17: 2546 | X17: 1.12 | Y17: 1.09 | Z17: 72.50% | AA17: 17.50% | AB17: 12741 | AC17: 7085 | AD17: 2972 | AE17: 856 | AF17: 172 | AG17: 16 | AH17: 4556 | AI17: 8300 | AJ17: 464 | AK17: 2883 | AL17: 170 | AM17: 29 | AN17: 1 | AO17: =AVERAGE(Tabla2[[#This Row],[total_kills]:[rating]]) -> 5694.4 | AP17: =VLOOKUP(Tabla2[[#This Row],[KPI]],$AS$2:$AT$5,2,1) -> Alto
A18: 11264 | B18: WARDELL | C18: Matthew Yu | D18: 24 | E18: Canada | F18: No team | G18: Ghost, Bee's Money Crew, Orgless | H18: 11627 | I18: 9979 | J18: 27.20% | K18: 74.2 | L18: 2.1 | M18: 609 | N18: 15901 | O18: 0.73 | P18: 0.1 | Q18: 0.63 | R18: 0.09 | S18: 0.1 | T18: 7692 | U18: K - D diff. | V18: 2057 | W18: 1399 | X18: 1.47 | Y18: 1.17 | Z18: 72.30% | AA18: 18.50% | AB18: 8209 | AC18: 4738 | AD18: 2139 | AE18: 663 | AF18: 138 | AG18: 14 | AH18: 1523 | AI18: 7327 | AJ18: 605 | AK18: 2109 | AL18: 94 | AM18: 12 | AN18: 1.13 | AO18: =AVERAGE(Tabla2[[#This Row],[total_kills]:[rating]]) -> 4043.9474 | AP18: =VLOOKUP(Tabla2[[#This Row],[KPI]],$AS$2:$AT$5,2,1) -> Medio
A19: 2544 | B19: remix | C19: Victor Monteiro | D19: 28 | E19: Brazil | F19: ODDIK | G19: Liberty, Redemption POA, UNO MILLE | H19: 7551 | I19: 6978 | J19: 27.30% | K19: 71.7 | L19: 2 | M19: 398 | N19: 10626 | O19: 0.71 | P19: 0.09 | Q19: 0.66 | R19: 0.09 | S19: 0.09 | T19: 5061 | U19: K - D diff. | V19: 1275 | W19: 942 | X19: 1.35 | Y19: 1.12 | Z19: 74.50% | AA19: 17.50% | AB19: 5565 | AC19: 3220 | AD19: 1314 | AE19: 418 | AF19: 96 | AG19: 13 | AH19: 1140 | AI19: 4956 | AJ19: 247 | AK19: 1168 | AL19: 43 | AM19: 16 | AN19: 1.07 | AO19: =AVERAGE(Tabla2[[#This Row],[total_kills]:[rating]]) -> 2551.45 | AP19: =VLOOKUP(Tabla2[[#This Row],[KPI]],$AS$2:$AT$5,2,1) -> Bajo
A20: 11748 | B20: raafa | C20: Rafael Lima | D20: 28 | E20: Brazil | F20: No team | G20: W7M, Keyd | H20: 11650 | I20: 10558 | J20: 27.40% | K20: 72.4 | L20: 3.7 | M20: 640 | N20: 16832 | O20: 0.69 | P20: 0.11 | Q20: 0.63 | R20: 0.07 | S20: 0.08 | T20: 7934 | U20: K - D diff. | V20: 1948 | W20: 1683 | X20: 1.16 | Y20: 1.08 | Z20: 76.30% | AA20: 17.10% | AB20: 8898 | AC20: 5105 | AD20: 2087 | AE20: 606 | AF20: 127 | AG20: 9 | AH20: 3059 | AI20: 5846 | AJ20: 589 | AK20: 2008 | AL20: 157 | AM20: 29 | AN20: 1.07 | AO20: =AVERAGE(Tabla2[[#This Row],[total_kills]:[rating]]) -> 4198.1579 | AP20: =VLOOKUP(Tabla2[[#This Row],[KPI]],$AS$2:$AT$5,2,1) -> Medio
A21: 7964 | B21: cadiaN | C21: Casper MÃ¸ller | D21: 27 | E21: Denmark | F21: Heroic | G21: Heroic, Rogue, SK | H21: 27065 | I21: 24531 | J21: 27.60% | K21: 73.3 | L21: 4.6 | M21: 1475 | N21: 38976 | O21: 0.69 | P21: 0.11 | Q21: 0.63 | R21: 0.09 | S21: 0.08 | T21: 18532 | U21: K - D diff. | V21: 4972 | W21: 3775 | X21: 1.32 | Y21: 1.14 | Z21: 75.30% | AA21: 18.60% | AB21: 20444 | AC21: 12006 | AD21: 4844 | AE21: 1390 | AF21: 268 | AG21: 24 | AH21: 6605 | AI21: 13070 | AJ21: 2144 | AK21: 4790 | AL21: 367 | AM21: 172 | AN21: 1.04 | AO21: =AVERAGE(Tabla2[[#This Row],[total_kills]:[rating]]) -> 9760.5263 | AP21: =VLOOKUP(Tabla2[[#This Row],[KPI]],$AS$2:$AT$5,2,1) -> Superior
A22: 10698 | B22: kolor | C22: ÃdÃ¡m Domoszlay | D22: 22 | E22: Hungary | F22: cowana | G22: GameAgents, Budapest Five, EURONICS | H22: 10309 | I22: 10009 | J22: 27.60% | K22: 73.3 | L22: 2.1 | M22: 558 | N22: 14585 | O22: 0.71 | P22: 0.11 | Q22: 0.69 | R22: 0.1 | S22: 0.12 | T22: 6933 | U22: K - D diff. | V22: 1744 | W22: 1525 | X22: 1.14 | Y22: 1.09 | Z22: 73.50% | AA22: 18.50% | AB22: 7652 | AC22: 4414 | AD22: 1815 | AE22: 563 | AF22: 129 | AG22: 12 | AH22: 2297 | AI22: 5702 | AJ22: 513 | AK22: 1717 | AL22: 82 | AM22: 24 | AN22: 1.05 | AO22: =AVERAGE(Tabla2[[#This Row],[total_kills]:[rating]]) -> 3714.8947 | AP22: =VLOOKUP(Tabla2[[#This Row],[KPI]],$AS$2:$AT$5,2,1) -> Medio
A23: 1088 | B23: liTTle | C23: Anatoliy Yashin | D23: 33 | E23: Russia | F23: HellRaisers | G23: forZe, RuSh3D, Spartak, Enso | H23: 9317 | I23: 7766 | J23: 27.70% | K23: 78.5 | L23: 2.6 | M23: 457 | N23: 12154 | O23: 0.77 | P23: 0.1 | Q23: 0.64 | R23: 0.07 | S23: 0.09 | T23: 6279 | U23: K - D diff. | V23: 1595 | W23: 1041 | X23: 1.53 | Y23: 1.18 | Z23: 71.60% | AA23: 19.00% | AB23: 5875 | AC23: 3952 | AD23: 1735 | AE23: 484 | AF23: 99 | AG23: 9 | AH23: 1248 | AI23: 5656 | AJ23: 105 | AK23: 2206 | AL23: 112 | AM23: 7 | AN23: 1.12 | AO23: =AVERAGE(Tabla2[[#This Row],[total_kills]:[rating]]) -> 3163 | AP23: =VLOOKUP(Tabla2[[#This Row],[KPI]],$AS$2:$AT$5,2,1) -> Bajo
A24: 16920 | B24: sh1ro | C24: Dmitry Sokolov | D24: 21 | E24: Russia | F24: Cloud9 | G24: Gambit Youngsters, Gambit | H24: 18091 | I24: 12492 | J24: 27.80% | K24: 78.6 | L24: 3.9 | M24: 884 | N24: 23451 | O24: 0.77 | P24: 0.11 | Q24: 0.53 | R24: 0.08 | S24: 0.11 | T24: 11950 | U24: K - D diff. | V24: 2705 | W24: 1383 | X24: 1.96 | Y24: 1.15 | Z24: 77.00% | AA24: 16.20% | AB24: 11501 | AC24: 7416 | AD24: 3208 | AE24: 1075 | AF24: 221 | AG24: 30 | AH24: 3791 | AI24: 10580 | AJ24: 550 | AK24: 3008 | AL24: 175 | AM24: 70 | AN24: 1.26 | AO24: =AVERAGE(Tabla2[[#This Row],[total_kills]:[rating]]) -> 5925.3158 | AP24: =VLOOKUP(Tabla2[[#This Row],[KPI]],$AS$2:$AT$5,2,1) -> Alto
A25: 11271 | B25: smooya | C25: Owen Butterfield | D25: 22 | E25: United Kingdom | F25: No team | G25: BIG, Movistar Riders, Epsilon | H25: 18466 | I25: 14617 | J25: 27.80% | K25: 79.3 | L25: 2.5 | M25: 888 | N25: 23515 | O25: 0.79 | P25: 0.1 | Q25: 0.62 | R25: 0.08 | S25: 0.1 | T25: 11971 | U25: K - D diff. | V25: 3187 | W25: 2183 | X25: 1.46 | Y25: 1.19 | Z25: 76.10% | AA25: 19.80% | AB25: 11544 | AC25: 7188 | AD25: 3367 | AE25: 1141 | AF25: 254 | AG25: 21 | AH25: 4786 | AI25: 9692 | AJ25: 584 | AK25: 3283 | AL25: 141 | AM25: 31 | AN25: 1.2 | AO25: =AVERAGE(Tabla2[[#This Row],[total_kills]:[rating]]) -> 6150.4737 | AP25: =VLOOKUP(Tabla2[[#This Row],[KPI]],$AS$2:$AT$5,2,1) -> Alto
A26: 8783 | B26: JUGi | C26: Jakob Hansen | D26: 25 | E26: Denmark | F26: No team | G26: Heroic, OpTic, Tricked, North | H26: 17527 | I26: 14851 | J26: 27.80% | K26: 74.1 | L26: 2.4 | M26: 940 | N26: 24427 | O26: 0.72 | P26: 0.1 | Q26: 0.61 | R26: 0.08 | S26: 0.1 | T26: 11901 | U26: K - D diff. | V26: 2942 | W26: 1904 | X26: 1.55 | Y26: 1.14 | Z26: 74.70% | AA26: 17.50% | AB26: 12526 | AC26: 7630 | AD26: 3146 | AE26: 913 | AF26: 194 | AG26: 18 | AH26: 4048 | AI26: 8877 | AJ26: 660 | AK26: 3768 | AL26: 177 | AM26: 31 | AN26: 1.09 | AO26: =AVERAGE(Tabla2[[#This Row],[total_kills]:[rating]]) -> 6130.5263 | AP26: =VLOOKUP(Tabla2[[#This Row],[KPI]],$AS$2:$AT$5,2,1) -> Alto
A27: 11219 | B27: CeRq | C27: Tsvetelin Dimitrov | D27: 22 | E27: Bulgaria | F27: Evil Geniuses | G27: Evil Geniuses, NRG, Outlaws | H27: 22812 | I27: 19387 | J27: 27.90% | K27: 74.2 | L27: 2.4 | M27: 1199 | N27: 31114 | O27: 0.73 | P27: 0.1 | Q27: 0.62 | R27: 0.1 | S27: 0.11 | T27: 15199 | U27: K - D diff. | V27: 3923 | W27: 2745 | X27: 1.43 | Y27: 1.15 | Z27: 75.10% | AA27: 18.00% | AB27: 15915 | AC27: 9524 | AD27: 4043 | AE27: 1347 | AF27: 264 | AG27: 21 | AH27: 5642 | AI27: 12614 | AJ27: 716 | AK27: 3714 | AL27: 150 | AM27: 30 | AN27: 1.14 | AO27: =AVERAGE(Tabla2[[#This Row],[total_kills]:[rating]]) -> 7913.6316 | AP27: =VLOOKUP(Tabla2[[#This Row],[KPI]],$AS$2:$AT$5,2,1) -> Superior
A28: 7403 | B28: WorldEdit | C28: Georgi Yaskin | D28: 30 | E28: Russia | F28: No team | G28: FlipSid3, pro100, Winstrike | H28: 25226 | I28: 22750 | J28: 28.00% | K28: 75 | L28: 2.6 | M28: 1328 | N28: 34716 | O28: 0.73 | P28: 0.12 | Q28: 0.66 | R28: 0.08 | S28: 0.08 | T28: 16893 | U28: K - D diff. | V28: 4415 | W28: 3319 | X28: 1.33 | Y28: 1.14 | Z28: 73.30% | AA28: 18.80% | AB28: 17823 | AC28: 10626 | AD28: 4553 | AE28: 1414 | AF28: 269 | AG28: 31 | AH28: 5963 | AI28: 13131 | AJ28: 1045 | AK28: 4780 | AL28: 244 | AM28: 82 | AN28: 1.07 | AO28: =AVERAGE(Tabla2[[#This Row],[total_kills]:[rating]]) -> 8434.15 | AP28: =VLOOKUP(Tabla2[[#This Row],[KPI]],$AS$2:$AT$5,2,1) -> Superior
A29: 964 | B29: mou | C29: Rustem Telepov | D29: 30 | E29: Kazakhstan | F29: No team | G29: Gambit, K23, HellRaisers, Syman | H29: 28048 | I29: 25564 | J29: 28.00% | K29: 73.9 | L29: 4 | M29: 1489 | N29: 39475 | O29: 0.71 | P29: 0.11 | Q29: 0.65 | R29: 0.08 | S29: 0.09 | T29: 18989 | U29: K - D diff. | V29: 4836 | W29: 3930 | X29: 1.23 | Y29: 1.11 | Z29: 74.30% | AA29: 17.80% | AB29: 20486 | AC29: 12087 | AD29: 5072 | AE29: 1536 | AF29: 274 | AG29: 20 | AH29: 6302 | AI29: 15808 | AJ29: 813 | AK29: 4672 | AL29: 413 | AM29: 77 | AN29: 1.05 | AO29: =AVERAGE(Tabla2[[#This Row],[total_kills]:[rating]]) -> 9494.75 | AP29: =VLOOKUP(Tabla2[[#This Row],[KPI]],$AS$2:$AT$5,2,1) -> Superior
A30: 4373 | B30: EasTor | C30: Rajohn Linato | D30: 28 | E30: Spain | F30: No team | G30: Movistar Riders, OFFSET | H30: 9017 | I30: 8646 | J30: 28.30% | K30: 68.7 | L30: 2.8 | M30: 500 | N30: 13298 | O30: 0.68 | P30: 0.09 | Q30: 0.65 | R30: 0.1 | S30: 0.1 | T30: 6177 | U30: K - D diff. | V30: 1530 | W30: 1214 | X30: 1.26 | Y30: 1.09 | Z30: 72.20% | AA30: 16.70% | AB30: 7121 | AC30: 4014 | AD30: 1616 | AE30: 431 | AF30: 102 | AG30: 14 | AH30: 1874 | AI30: 5193 | AJ30: 474 | AK30: 1390 | AL30: 86 | AM30: 17 | AN30: 1.01 | AO30: =AVERAGE(Tabla2[[#This Row],[total_kills]:[rating]]) -> 3300.7368 | AP30: =VLOOKUP(Tabla2[[#This Row],[KPI]],$AS$2:$AT$5,2,1) -> Medio
A31: 16847 | B31: mhL | C31: MiÅ‚osz Knasiak | D31: 20 | E31: Poland | F31: MOUZ NXT | G31: MOUZ NXT, AGO | H31: 10241 | I31: 8484 | J31: 28.50% | K31: 80 | L31: 3.8 | M31: 498 | N31: 13378 | O31: 0.77 | P31: 0.12 | Q31: 0.63 | R31: 0.1 | S31: 0.11 | T31: 6773 | U31: K - D diff. | V31: 1656 | W31: 1114 | X31: 1.49 | Y31: 1.15 | Z31: 76.70% | AA31: 18.40% | AB31: 6605 | AC31: 4156 | AD31: 1896 | AE31: 596 | AF31: 120 | AG31: 5 | AH31: 2444 | AI31: 5801 | AJ31: 181 | AK31: 1687 | AL31: 153 | AM31: 16 | AN31: 1.17 | AO31: =AVERAGE(Tabla2[[#This Row],[total_kills]:[rating]]) -> 3294.2 | AP31: =VLOOKUP(Tabla2[[#This Row],[KPI]],$AS$2:$AT$5,2,1) -> Bajo
A32: 20097 | B32: h4rn | C32: Deyvid Benchev | D32: 22 | E32: Bulgaria | F32: Enterprise | G32: FATE, Fiend | H32: 10915 | I32: 9130 | J32: 28.60% | K32: 74.1 | L32: 3.3 | M32: 566 | N32: 15106 | O32: 0.72 | P32: 0.1 | Q32: 0.6 | R32: 0.09 | S32: 0.09 | T32: 7367 | U32: K - D diff. | V32: 1771 | W32: 1181 | X32: 1.5 | Y32: 1.12 | Z32: 75.40% | AA32: 17.30% | AB32: 7739 | AC32: 4690 | AD32: 1941 | AE32: 614 | AF32: 109 | AG32: 13 | AH32: 2778 | AI32: 6103 | AJ32: 221 | AK32: 1683 | AL32: 117 | AM32: 64 | AN32: 1.14 | AO32: =AVERAGE(Tabla2[[#This Row],[total_kills]:[rating]]) -> 3795.1579 | AP32: =VLOOKUP(Tabla2[[#This Row],[KPI]],$AS$2:$AT$5,2,1) -> Medio
A33: 695 | B33: allu | C33: Aleksi Jalli | D33: 30 | E33: Finland | F33: temp | G33: ENCE, NIP, FaZe | H33: 31366 | I33: 27037 | J33: 28.60% | K33: 74.9 | L33: 3.6 | M33: 1615 | N33: 42334 | O33: 0.74 | P33: 0.11 | Q33: 0.64 | R33: 0.08 | S33: 0.09 | T33: 21027 | U33: K - D diff. | V33: 5021 | W33: 3302 | X33: 1.52 | Y33: 1.13 | Z33: 76.70% | AA33: 17.50% | AB33: 21307 | AC33: 13181 | AD33: 5782 | AE33: 1697 | AF33: 336 | AG33: 31 | AH33: 8713 | AI33: 15102 | AJ33: 1531 | AK33: 5345 | AL33: 503 | AM33: 216 | AN33: 1.09 | AO33: =AVERAGE(Tabla2[[#This Row],[total_kills]:[rating]]) -> 10812.947 | AP33: =VLOOKUP(Tabla2[[#This Row],[KPI]],$AS$2:$AT$5,2,1) -> Superior
A34: 13228 | B34: Voltage | C34: Logan Long | D34: 22 | E34: United States | F34: ONET4P | G34: The Quest, Triumph, SoaR, Dignitas | H34: 7407 | I34: 6823 | J34: 28.60% | K34: 67.6 | L34: 2.8 | M34: 438 | N34: 11278 | O34: 0.66 | P34: 0.09 | Q34: 0.6 | R34: 0.09 | S34: 0.1 | T34: 5139 | U34: K - D diff. | V34: 1165 | W34: 896 | X34: 1.3 | Y34: 1.05 | Z34: 73.70% | AA34: 14.90% | AB34: 6139 | AC34: 3402 | AD34: 1288 | AE34: 376 | AF34: 64 | AG34: 9 | AH34: 1985 | AI34: 3683 | AJ34: 379 | AK34: 1257 | AL34: 94 | AM34: 18 | AN34: 1.05 | AO34: =AVERAGE(Tabla2[[#This Row],[total_kills]:[rating]]) -> 2728.4211 | AP34: =VLOOKUP(Tabla2[[#This Row],[KPI]],$AS$2:$AT$5,2,1) -> Bajo
A35: 17930 | B35: wiz | C35: Jerric Jiang | D35: 21 | E35: United States | F35: EG.CD | G35: RBG, Carpe Diem | H35: 8682 | I35: 8582 | J35: 28.70% | K35: 68.9 | L35: 4.3 | M35: 501 | N35: 13291 | O35: 0.65 | P35: 0.1 | Q35: 0.65 | R35: 0.09 | S35: 0.09 | T35: 6034 | U35: K - D diff. | V35: 1323 | W35: 1080 | X35: 1.23 | Y35: 1.03 | Z35: 73.60% | AA35: 14.60% | AB35: 7257 | AC35: 3982 | AD35: 1557 | AE35: 405 | AF35: 79 | AG35: 11 | AH35: 2235 | AI35: 4685 | AJ35: 217 | AK35: 1434 | AL35: 110 | AM35: 37 | AN35: 1.02 | AO35: =AVERAGE(Tabla2[[#This Row],[total_kills]:[rating]]) -> 3236.9474 | AP35: =VLOOKUP(Tabla2[[#This Row],[KPI]],$AS$2:$AT$5,2,1) -> Bajo
A36: 8565 | B36: HEN1 | C36: Henrique Teles | D36: 27 | E36: Brazil | F36: No team | G36: Immortals, FURIA, Luminosity | H36: 20188 | I36: 16640 | J36: 28.80% | K36: 74.8 | L36: 3.8 | M36: 1101 | N36: 28598 | O36: 0.71 | P36: 0.12 | Q36: 0.58 | R36: 0.08 | S36: 0.09 | T36: 13719 | U36: K - D diff. | V36: 3022 | W36: 1984 | X36: 1.52 | Y36: 1.08 | Z36: 74.40% | AA36: 14.90% | AB36: 14879 | AC36: 8790 | AD36: 3642 | AE36: 1054 | AF36: 213 | AG36: 20 | AH36: 5239 | AI36: 10163 | AJ36: 896 | AK36: 3609 | AL36: 230 | AM36: 98 | AN36: 1.1 | AO36: =AVERAGE(Tabla2[[#This Row],[total_kills]:[rating]]) -> 7057.1053 | AP36: =VLOOKUP(Tabla2[[#This Row],[KPI]],$AS$2:$AT$5,2,1) -> Superior
A37: 17793 | B37: smiley | C37: Algat Abdul | D37: 25 | E37: Kazakhstan | F37: Unique | G37: Unique, 100PG, Se7en | H37: 8764 | I37: 8133 | J37: 28.80% | K37: 72.5 | L37: 3.3 | M37: 478 | N37: 12883 | O37: 0.68 | P37: 0.1 | Q37: 0.63 | R37: 0.08 | S37: 0.09 | T37: 6052 | U37: K - D diff. | V37: 1593 | W37: 1167 | X37: 1.37 | Y37: 1.13 | Z37: 74.20% | AA37: 18.50% | AB37: 6831 | AC37: 3944 | AD37: 1597 | AE37: 425 | AF37: 79 | AG37: 7 | AH37: 2009 | AI37: 5245 | AJ37: 213 | AK37: 1233 | AL37: 75 | AM37: 13 | AN37: 1.07 | AO37: =AVERAGE(Tabla2[[#This Row],[total_kills]:[rating]]) -> 3196.8947 | AP37: =VLOOKUP(Tabla2[[#This Row],[KPI]],$AS$2:$AT$5,2,1) -> Bajo
A38: 9288 | B38: TOR | C38: Tosapol Saekow | D38: 29 | E38: Thailand | F38: No team | G38: Signature, Beyond | H38: 8271 | I38: 7614 | J38: 28.90% | K38: 77 | L38: 2.9 | M38: 452 | N38: 11472 | O38: 0.72 | P38: 0.12 | Q38: 0.66 | R38: 0.08 | S38: 0.09 | T38: 5547 | U38: K - D diff. | V38: 1363 | W38: 1102 | X38: 1.24 | Y38: 1.1 | Z38: 79.10% | AA38: 17.90% | AB38: 5925 | AC38: 3512 | AD38: 1469 | AE38: 454 | AF38: 101 | AG38: 11 | AH38: 3205 | AI38: 3251 | AJ38: 528 | AK38: 1231 | AL38: 54 | AM38: 23 | AN38: 1.06 | AO38: =AVERAGE(Tabla2[[#This Row],[total_kills]:[rating]]) -> 2783.1 | AP38: =VLOOKUP(Tabla2[[#This Row],[KPI]],$AS$2:$AT$5,2,1) -> Bajo
A39: 7383 | B39: zqkS | C39: Caio Fonseca | D39: 30 | E39: Brazil | F39: Corinthians | G39: Imperial, Yeah, Keyd | H39: 13308 | I39: 12620 | J39: 28.90% | K39: 69.5 | L39: 3.8 | M39: 780 | N39: 20206 | O39: 0.66 | P39: 0.12 | Q39: 0.62 | R39: 0.09 | S39: 0.09 | T39: 9254 | U39: K - D diff. | V39: 2398 | W39: 1798 | X39: 1.33 | Y39: 1.11 | Z39: 73.90% | AA39: 17.40% | AB39: 10952 | AC39: 6105 | AD39: 2389 | AE39: 635 | AF39: 114 | AG39: 11 | AH39: 2972 | AI39: 7363 | AJ39: 575 | AK39: 2187 | AL39: 176 | AM39: 71 | AN39: 1 | AO39: =AVERAGE(Tabla2[[#This Row],[total_kills]:[rating]]) -> 4695.75 | AP39: =VLOOKUP(Tabla2[[#This Row],[KPI]],$AS$2:$AT$5,2,1) -> Medio
